Workbook

Sheet Major-1 (NARS)
A2: LEVEL | B2: SEMESTER | C2: Code | D2: Title | E2: Lec | F2: Tut | G2: Lab | H2: Prerequisites | I2: Com. Uni. | J2: Elec. Univ. | K2: Com. College | L2: Com. Discipline | M2: Major Req. | N2: Elec Major | O2: Hum. & Social Sci. | P2: Math & Basic Sci. | Q2: Basic Eng. Sci. | R2: Computer App. | S2: Applied Eng. Sci. | T2: Project & PT | U2: Discretional
A3: 1 | B3: 1 | C3: EGL 111 | D3: English I | H3: TOFEL>500 | I3: 0 | O3: 0
A4: 1 | B4: 2 | C4: EGL 112 | D4: English II | H4: EGL111 | I4: 0 | O4: 0
A5: 2 | B5: 3 | C5: EGL 213 | D5: Writing Skills | E5: 3 | F5: 0 | G5: 0 | H5: EGL112 | I5: 3 | O5: 3
A6: 2 | B6: 4 | C6: EGL 214 | D6: Communication and Presentation Skills | E6: 3 | F6: 0 | G6: 0 | H6: EGL112 | I6: 3 | O6: 3
A7: 1 | B7: 1 | C7: CSC 111 | D7: Computer and Information Skills | E7: 1 | F7: 2 | G7: 2 | I7: 3 | R7: 3
A8: 1 | B8: 2 | C8: HUM E1 | D8: Humanities and Social Sciences Electives | E8: 3 | F8: 0 | G8: 0 | J8: 3 | O8: 3
A9: 1 | B9: 2 | C9: ECE 151 | D9: Introduction to Programming | E9: 2 | F9: 0 | G9: 2 | K9: 3 | R9: 3
A10: 1 | B10: 1 | C10: INT E1 | D10: Engineering History Electives | E10: 2 | F10: 2 | G10: 0 | J10: 3 | O10: 3
A11: 1 | B11: 8 | C11: EBS 111 | D11: Selected Topics in Entrepreneurship | E11: 2 | F11: 2 | G11: 0 | K11: 3 | O11: 3
A12: 4 | B12: 8 | C12: INT E2 | D12: Sustainable Development Electives | E12: 2 | F12: 2 | G12: 0 | J12: 3 | S12: 3
A13: 1 | B13: 1 | C13: MTH 111 | D13: Analytical Geometry and Calculus I | E13: 2 | F13: 2 | G13: 0 | K13: 3 | P13: 3
A14: 1 | B14: 2 | C14: MTH 113 | D14: Probability & Statistics for Engineers | E14: 2 | F14: 2 | G14: 0 | K14: 3 | P14: 3
A15: 2 | B15: 3 | C15: MTH 214 | D15: Linear Algebra & Introduction to Machine Learning | E15: 2 | F15: 2 | G15: 0 | K15: 3 | P15: 3
A16: 1 | B16: 1 | C16: MEC 111 | D16: Engineering Mechanics I | E16: 2 | F16: 2 | G16: 0 | K16: 3 | P16: 3
A17: 1 | B17: 1 | C17: INT 121 | D17: Engineering Drawing | E17: 2 | F17: 0 | G17: 2 | K17: 3 | Q17: 3
A18: 1 | B18: 1 | C18: PHY 111 | D18: Physics I | E18: 2 | F18: 2 | G18: 1 | K18: 3 | P18: 3
A19: 2 | B19: 2 | C19: CVL 211 | D19: Structural Analysis-1 | E19: 2 | F19: 2 | G19: 0 | H19: MEC111 | L19: 3 | Q19: 3
A20: 2 | B20: 3 | C20: CVL 212 | D20: Structural Analysis-2 | E20: 2 | F20: 2 | G20: 0 | H20: CVL211 | L20: 3 | Q20: 3
A21: 2 | B21: 3 | C21: CVL 221 | D21: Engineering Materials-1 | E21: 2 | F21: 1 | G21: 1 | L21: 3 | Q21: 3
A22: 2 | B22: 4 | C22: CVL 231 | D22: Construction Project Management | E22: 2 | F22: 2 | G22: 0 | L22: 3 | Q22: 3
A23: 2 | B23: 3 | C23: CVL 281 | D23: Introduction to Surveying | E23: 1 | F23: 2 | G23: 2 | L23: 3 | Q23: 3
A24: 2 | B24: 3 | C24: CVL 282 | D24: Civil Engineering Drafting | E24: 1 | F24: 2 | G24: 2 | H24: MEC121 | L24: 3 | Q24: 3
A25: 3 | B25: 4 | C25: CVL 311 | D25: Reinforced Concrete Design-1 | E25: 2 | F25: 2 | G25: 0 | H25: CVL211 | L25: 3 | R25: 3
A26: 3 | B26: 5 | C26: CVL 312 | D26: Soil Mechanics | E26: 2 | F26: 1 | G26: 1 | H26: CVL221 | L26: 3 | S26: 3
A27: 3 | B27: 5 | C27: CVL 314 | D27: Reinforced Concrete Design-2 | E27: 2 | F27: 2 | G27: 0 | H27: CVL311 | L27: 3 | S27: 3
A28: 3 | B28: 6 | C28: CVL 315 | D28: Structural Steel Design | E28: 2 | F28: 2 | G28: 0 | H28: CVL212 | L28: 3 | S28: 3
A29: 3 | B29: 4 | C29: CVL 321 | D29: Engineering Materials-2 | E29: 2 | F29: 1 | G29: 1 | H29: CVL221 | L29: 3 | Q29: 3
A30: 3 | B30: 4 | C30: CVL 331 | D30: Construction Engineering and Methods | E30: 2 | F30: 2 | G30: 0 | L30: 3 | Q30: 3
A31: 3 | B31: 5 | C31: CVL 341 | D31: Fluid Mechanics | E31: 2 | F31: 1 | G31: 1 | H31: MTH215 | L31: 3 | Q31: 3
A32: 3 | B32: 4 | C32: CVL 391 | D32: Practical Training -1 | L32: 0 | T32: 0
A33: 3 | B33: 6 | C33: CVL 392 | D33: Practical Training -2 | H33: CVL391 (CO) | L33: 0 | T33: 0
A34: 4 | B34: 6 | C34: CVL 411 | D34: Design and Construction of Foundations | E34: 2 | F34: 2 | G34: 0 | H34: CVL312 | L34: 3 | S34: 3
A35: 4 | B35: 6 | C35: CVL 441 | D35: Fundamentals of Hydraulic Engineering | E35: 2 | F35: 1 | G35: 1 | H35: CVL341 | L35: 3 | Q35: 3
A36: 4 | B36: 6 | C36: CVL 451 | D36: Introduction to Transportation and Highway Engineering | E36: 2 | F36: 1 | G36: 1 | L36: 3 | Q36: 3
A37: 4 | B37: 7 | C37: CVL 493 | D37: Graduation Project I | E37: 1 | F37: 0 | G37: 4 | L37: 3 | T37: 3
A38: 4 | B38: 8 | C38: CVL 494 | D38: Graduation Project II | E38: 1 | F38: 0 | G38: 4 | H38: CVL493 (CO) | L38: 3 | T38: 3
A39: 1 | B39: 2 | C39: CHM 111 | D39: Chemistry | E39: 2 | F39: 1 | G39: 1 | L39: 3 | P39: 3
A40: 1 | B40: 2 | C40: MTH 112 | D40: Calculus II | E40: 2 | F40: 2 | G40: 0 | H40: MTH111 (CO) | L40: 3 | P40: 3
A41: 2 | B41: 4 | C41: MTH 215 | D41: Differential Equations | E41: 2 | F41: 2 | G41: 0 | H41: MTH112 | L41: 3 | P41: 3
...

Sheet Major-1 (Competencies)
A1: Color Coding
A2: University Requirements
A3: Faculty of Engineering Requirements | E3: Lec | F3: Tut | G3: Lab | H3: CH | I3: ECTS | J3: SWL | N3: U1 | O3: U2 | P3: U3 | Q3: U4 | R3: U5 | S3: U6 | T3: A1 | U3: A2 | V3: A3 | W3: A4 | X3: A5 | Y3: A6 | Z3: A7 | AA3: A8 | AB3: A9 | AC3: A 10 | AD3: B1 | AE3: B2 | AF3: B3 | AG3: B4 | AH3: C1 | AI3: C2 | AJ3: C3 | AK3: C4 | AL3: C5
A4: Basic Sciences Requirements | C4: EGL 111 | D4: English I | H4: 0 | I4: 0 | L4: CVL 211 | M4: Structural Analysis-1 | T4: X | AD4: X | AE4: X | AM4: =COUNTIF(N4:AL4,"*X*") -> 3
A5: Program Requirements | C5: EGL 112 | D5: English II | H5: 0 | I5: 0 | L5: CVL 212 | M5: Structural Analysis-2 | T5: X | AD5: X | AE5: X | AM5: =COUNTIF(N5:AL5,"*X*") -> 3
A6: Major Requirements (Specialization) | C6: EGL 213 | D6: Writing Skills | E6: 3 | F6: 0 | G6: 0 | H6: 3 | I6: 5 | J6: 125 | L6: CVL 221 | M6: Engineering Materials-1 | U6: X | AD6: X | AF6: X | AM6: =COUNTIF(N6:AL6,"*X*") -> 3
A7: Major Electives | C7: EGL 214 | D7: Communication and Presentation Skills | E7: 3 | F7: 0 | G7: 0 | H7: 3 | I7: 5 | J7: 125 | L7: CVL 231 | M7: Construction Project Management | W7: X | AF7: X | AG7: X | AM7: =COUNTIF(N7:AL7,"*X*") -> 3
C8: CSC 111 | D8: Computer and Information Skills | E8: 1 | F8: 2 | G8: 2 | H8: 3 | I8: 5 | J8: 125 | L8: CVL 281 | M8: Introduction to Surveying | Y8: X | Z8: X | AD8: X | AM8: =COUNTIF(N8:AL8,"*X*") -> 3
C9: HUM E1 | D9: Humanities and Social Sciences Electives | E9: 3 | F9: 0 | G9: 0 | H9: 3 | I9: 5 | J9: 125 | L9: CVL 282 | M9: Civil Engineering Drafting | Y9: X | AA9: X | AD9: X | AM9: =COUNTIF(N9:AL9,"*X*") -> 3
D10: =COUNTA(D4:D9) -> 6 | E10: =SUM(E4:E9) -> 10 | F10: =SUM(F4:F9) -> 2 | G10: =SUM(G4:G9) -> 2 | H10: =SUM(H4:H9) -> 12 | I10: =SUM(I4:I9) -> 20 | J10: =SUM(J4:J9) -> 500 | L10: CVL 311 | M10: Reinforced Concrete Design-1 | V10: X | W10: X | AE10: X | AM10: =COUNTIF(N10:AL10,"*X*") -> 3
C11: MTH 111 | D11: Analytical Geometry and Calculus I | E11: 2 | F11: 2 | G11: 0 | H11: 3 | I11: 5 | J11: 125 | L11: CVL 312 | M11: Soil Mechanics | U11: X | AD11: X | AE11: X | AM11: =COUNTIF(N11:AL11,"*X*") -> 3
C12: MTH 113 | D12: Probability & Statistics for Engineers | E12: 2 | F12: 2 | G12: 0 | H12: 3 | I12: 5 | J12: 125 | L12: CVL 314 | M12: Reinforced Concrete Design-2 | V12: X | W12: X | AE12: X | AM12: =COUNTIF(N12:AL12,"*X*") -> 3
C13: MTH 214 | D13: Linear Algebra & Introduction to Machine Learning | E13: 2 | F13: 2 | G13: 0 | H13: 3 | I13: 5 | J13: 125 | L13: CVL 315 | M13: Structural Steel Design | V13: X | W13: X | AE13: X | AM13: =COUNTIF(N13:AL13,"*X*") -> 3
C14: MEC 111 | D14: Engineering Mechanics I | E14: 2 | F14: 2 | G14: 0 | H14: 3 | I14: 5 | J14: 125 | L14: CVL 321 | M14: Engineering Materials-2 | U14: X | AD14: X | AF14: X | AM14: =COUNTIF(N14:AL14,"*X*") -> 3
C15: INT 121 | D15: Engineering Drawing | E15: 2 | F15: 0 | G15: 2 | H15: 3 | I15: 5 | J15: 125 | L15: CVL 331 | M15: Construction Engineering and Methods | V15: X | AD15: X | AF15: X | AM15: =COUNTIF(N15:AL15,"*X*") -> 3
C16: PHY 111 | D16: Physics I | E16: 2 | F16: 2 | G16: 1 | H16: 3 | I16: 5 | J16: 125 | L16: CVL 341 | M16: Fluid Mechanics | T16: X | AD16: X | AE16: X | AM16: =COUNTIF(N16:AL16,"*X*") -> 3
C17: ECE 151 | D17: Introduction to Programming | E17: 2 | F17: 0 | G17: 2 | H17: 3 | I17: 5 | J17: 125 | L17: CVL 391 | M17: Practical Training -1 | Y17: X | Z17: X | AF17: X | AM17: =COUNTIF(N17:AL17,"*X*") -> 3
C18: INT E1 | D18: Engineering History Electives | E18: 2 | F18: 2 | G18: 0 | H18: 3 | I18: 5 | J18: 125 | L18: CVL 392 | M18: Practical Training -2 | Y18: X | Z18: X | AF18: X | AM18: =COUNTIF(N18:AL18,"*X*") -> 3
C19: INT E2 | D19: Sustainable Development Electives | E19: 2 | F19: 2 | G19: 0 | H19: 3 | I19: 5 | J19: 125 | L19: CVL 411 | M19: Design and Construction of Foundations | V19: X | W19: X | AE19: X | AM19: =COUNTIF(N19:AL19,"*X*") -> 3
C20: EBS 111 | D20: Selected Topics in Entrepreneurship | E20: 2 | F20: 2 | G20: 0 | H20: 3 | I20: 5 | J20: 125 | L20: CVL 441 | M20: Fundamentals of Hydraulic Engineering | U20: X | AD20: X | AE20: X | AM20: =COUNTIF(N20:AL20,"*X*") -> 3
D21: =COUNTA(D11:D20) -> 10 | E21: =SUM(E11:E20) -> 20 | F21: =SUM(F11:F20) -> 16 | G21: =SUM(G11:G20) -> 5 | H21: =SUM(H11:H20) -> 30 | I21: =SUM(I11:I20) -> 50 | J21: =SUM(J11:J20) -> 1250 | L21: CVL 451 | M21: Introduction to Transportation and Highway Engineering | V21: X | AE21: X | AF21: X | AM21: =COUNTIF(N21:AL21,"*X*") -> 3
C22: CVL 211 | D22: Structural Analysis-1 | E22: 2 | F22: 2 | G22: 0 | H22: 3 | I22: 5 | J22: 125 | L22: CVL 493 | M22: Graduation Project I | X22: X | AA22: X | AC22: X | AE22: X | AM22: =COUNTIF(N22:AL22,"*X*") -> 4
C23: CVL 212 | D23: Structural Analysis-2 | E23: 2 | F23: 2 | G23: 0 | H23: 3 | I23: 5 | J23: 125 | L23: CVL 494 | M23: Graduation Project II | AA23: X | AB23: X | AC23: X | AE23: X | AM23: =COUNTIF(N23:AL23,"*X*") -> 4
C24: CVL 221 | D24: Engineering Materials-1 | E24: 2 | F24: 1 | G24: 1 | H24: 3 | I24: 5 | J24: 125 | L24: CHM 111 | M24: Chemistry | T24: X | U24: X | W24: X | AM24: =COUNTIF(N24:AL24,"*X*") -> 3
C25: CVL 231 | D25: Construction Project Management | E25: 2 | F25: 2 | G25: 0 | H25: 3 | I25: 5 | J25: 125 | L25: MTH 112 | M25: Calculus II | T25: X | U25: X | X25: X | AM25: =COUNTIF(N25:AL25,"*X*") -> 3
C26: CVL 281 | D26: Introduction to Surveying | E26: 1 | F26: 2 | G26: 2 | H26: 3 | I26: 5 | J26: 125 | L26: MTH 215 | M26: Differential Equations | T26: X | U26: X | X26: X | AM26: =COUNTIF(N26:AL26,"*X*") -> 3
C27: CVL 282 | D27: Civil Engineering Drafting | E27: 1 | F27: 2 | G27: 2 | H27: 3 | I27: 5 | J27: 125 | L27: MTH 216 | M27: Numerical Methods | U27: X | V27: X | AM27: =COUNTIF(N27:AL27,"*X*") -> 2
C28: CVL 311 | D28: Reinforced Concrete Design-1 | E28: 2 | F28: 2 | G28: 0 | H28: 3 | I28: 5 | J28: 125 | L28: CVL 332 | M28: Quantity Surveying, Estimation and Specifications | AF28: X | AG28: X | AJ28: X | AM28: =COUNTIF(N28:AL28,"*X*") -> 3
C29: CVL 312 | D29: Soil Mechanics | E29: 2 | F29: 1 | G29: 1 | H29: 3 | I29: 5 | J29: 125 | L29: CVL 333 | M29: Civil Engineering Economics | AG29: X | AJ29: X | AM29: =COUNTIF(N29:AL29,"*X*") -> 2
C30: CVL 314 | D30: Reinforced Concrete Design-2 | E30: 2 | F30: 2 | G30: 0 | H30: 3 | I30: 5 | J30: 125 | L30: CVL 334 | M30: Construction Planning and Scheduling | AF30: X | AJ30: X | AK30: X | AM30: =COUNTIF(N30:AL30,"*X*") -> 3
C31: CVL 315 | D31: Structural Steel Design | E31: 2 | F31: 2 | G31: 0 | H31: 3 | I31: 5 | J31: 125 | L31: CVL 431 | M31: Value and Risk Management in Construction | AG31: X | AH31: X | AJ31: X | AL31: X | AM31: =COUNTIF(N31:AL31,"*X*") -> 4
C32: CVL 321 | D32: Engineering Materials-2 | E32: 2 | F32: 1 | G32: 1 | H32: 3 | I32: 5 | J32: 125 | L32: CVL 432 | M32: Contracts and Commercial Management | Y32: X | AG32: X | AI32: X | AM32: =COUNTIF(N32:AL32,"*X*") -> 3
C33: CVL 331 | D33: Construction Engineering and Methods | E33: 2 | F33: 2 | G33: 0 | H33: 3 | I33: 5 | J33: 125 | L33: CVL 433 | M33: Infrastructure Asset Management | W33: X | AF33: X | AI33: X | AL33: X | AM33: =COUNTIF(N33:AL33,"*X*") -> 4
C34: CVL 341 | D34: Fluid Mechanics | E34: 2 | F34: 1 | G34: 1 | H34: 3 | I34: 5 | J34: 125 | L34: CVL 434 | M34: Strategic Management in Construction | AF34: X | AG34: X | AH34: X | AI34: X | AM34: =COUNTIF(N34:AL34,"*X*") -> 4
C35: CVL 391 | D35: Practical Training-1 | H35: 0 | I35: 0 | L35: MTH 317 | M35: Introduction to Mathematical Optimization | T35: X | AD35: X | AL35: X | AM35: =COUNTIF(N35:AL35,"*X*") -> 3
C36: CVL 392 | D36: Practical Training-2 | H36: 0 | I36: 0 | L36: MTH 318 | M36: Advanced Probability and Statstics | T36: X | AD36: X | AL36: X | AM36: =COUNTIF(N36:AL36,"*X*") -> 3
C37: CVL 411 | D37: Design and Construction of Foundations | E37: 2 | F37: 2 | G37: 0 | H37: 3 | I37: 5 | J37: 125 | L37: MTH 319 | M37: Advanced Numerical Analysis | T37: X | AD37: X | AL37: X | AM37: =COUNTIF(N37:AL37,"*X*") -> 3
C38: CVL 441 | D38: Fundamentals of Hydraulic Engineering | E38: 2 | F38: 1 | G38: 1 | H38: 3 | I38: 5 | J38: 125 | L38: CVL 381 | M38: Computer applications in civil engineering | AD38: X | AM38: =COUNTIF(N38:AL38,"*X*") -> 1
C39: CVL 451 | D39: Introduction to Transportation and Highway Engineering | E39: 2 | F39: 1 | G39: 1 | H39: 3 | I39: 5 | J39: 125 | L39: CVL 413 | M39: Repair and Strengthening of Buildings | AD39: X | AF39: X | AK39: X | AM39: =COUNTIF(N39:AL39,"*X*") -> 3
C40: CVL 493 | D40: Graduation Project I | E40: 1 | F40: 0 | G40: 4 | H40: 3 | I40: 5 | J40: 125 | L40: CVL 422 | M40: Quality Control of Smart Materials | AD40: X | AK40: X | AM40: =COUNTIF(N40:AL40,"*X*") -> 2
...

Sheet CCE Major-1 (8 S)
C2: Requirements | D2: Credits and SWL | G2: Contact Hours | K2: TOR CR | L2: TOR % | M2: Actual % | S2: Program "Civil & Construction Engineering - CCE" Major-1 "Construction Engineering & Management" CEM [8-Semesters Study Plan]
D3: CH | E3: ECTS | F3: SWL | G3: Lec | H3: Tut | I3: Lab | J3: TT
C4: University Requirements | D4: {=SUM(SUM(D14:D21*$L14:$L21),SUM(U14:U21*$AC14:$AC21), SUM(D26:D33*$L26:$L33), SUM(U26:U33*$AC26:$AC33), SUM(D38:D45*$L38:$L45), SUM(U38:U45*$AC38:$AC45),SUM(D50:D56*$L50:$L56), SUM(U50:U56*$AC50:$AC56))} -> 12 | E4: {=SUM(SUM(E14:E21*$L14:$L21),SUM(V14:V21*$AC14:$AC21), SUM(E26:E33*$L26:$L33), SUM(V26:V33*$AC26:$AC33), SUM(E38:E45*$L38:$L45), SUM(V38:V45*$AC38:$AC45),SUM(E50:E56*$L50:$L56), SUM(V50:V56*$AC50:$AC56))} -> 20 | F4: {=SUM(SUM(F14:F21*$L14:$L21),SUM(W14:W21*$AC14:$AC21), SUM(F26:F33*$L26:$L33), SUM(W26:W33*$AC26:$AC33), SUM(F38:F45*$L38:$L45), SUM(W38:W45*$AC38:$AC45),SUM(F50:F56*$L50:$L56), SUM(W50:W56*$AC50:$AC56))} -> 500 | G4: {=SUM(SUM(G14:G21*$L14:$L21),SUM(X14:X21*$AC14:$AC21), SUM(G26:G33*$L26:$L33), SUM(X26:X33*$AC26:$AC33), SUM(G38:G45*$L38:$L45), SUM(X38:X45*$AC38:$AC45),SUM(G50:G56*$L50:$L56), SUM(X50:X56*$AC50:$AC56))} -> 10 | H4: {=SUM(SUM(H14:H21*$L14:$L21),SUM(Y14:Y21*$AC14:$AC21), SUM(H26:H33*$L26:$L33), SUM(Y26:Y33*$AC26:$AC33), SUM(H38:H45*$L38:$L45), SUM(Y38:Y45*$AC38:$AC45),SUM(H50:H56*$L50:$L56), SUM(Y50:Y56*$AC50:$AC56))} -> 2 | I4: {=SUM(SUM(I14:I21*$L14:$L21),SUM(Z14:Z21*$AC14:$AC21), SUM(I26:I33*$L26:$L33), SUM(Z26:Z33*$AC26:$AC33), SUM(I38:I45*$L38:$L45), SUM(Z38:Z45*$AC38:$AC45),SUM(I50:I56*$L50:$L56), SUM(Z50:Z56*$AC50:$AC56))} -> 2 | J4: {=SUM(SUM(J14:J21*$L14:$L21),SUM(AA14:AA21*$AC14:$AC21), SUM(J26:J33*$L26:$L33), SUM(AA26:AA33*$AC26:$AC33), SUM(J38:J45*$L38:$L45), SUM(AA38:AA45*$AC38:$AC45),SUM(J50:J56*$L50:$L56), SUM(AA50:AA56*$AC50:$AC56))} -> 14 | K4: 12 (Min.) | L4: 0.08 | M4: =D4/$D$10 -> 0.083333333
C5: Faculty of Engineering Requirements | D5: {=SUM(SUM(D14:D21*$M14:$M21),SUM(U14:U21*$AD14:$AD21), SUM(D26:D33*$M26:$M33), SUM(U26:U33*$AD26:$AD33), SUM(D38:D45*$M38:$M45), SUM(U38:U45*$AD38:$AD45),SUM(D50:D56*$M50:$M56), SUM(U50:U56*$AD50:$AD56))} -> 30 | E5: {=SUM(SUM(E14:E21*$M14:$M21),SUM(V14:V21*$AD14:$AD21), SUM(E26:E33*$M26:$M33), SUM(V26:V33*$AD26:$AD33), SUM(E38:E45*$M38:$M45), SUM(V38:V45*$AD38:$AD45),SUM(E50:E56*$M50:$M56), SUM(V50:V56*$AD50:$AD56))} -> 50 | F5: {=SUM(SUM(F14:F21*$M14:$M21),SUM(W14:W21*$AD14:$AD21), SUM(F26:F33*$M26:$M33), SUM(W26:W33*$AD26:$AD33), SUM(F38:F45*$M38:$M45), SUM(W38:W45*$AD38:$AD45),SUM(F50:F56*$M50:$M56), SUM(W50:W56*$AD50:$AD56))} -> 1250 | G5: {=SUM(SUM(G14:G21*$M14:$M21),SUM(X14:X21*$AD14:$AD21), SUM(G26:G33*$M26:$M33), SUM(X26:X33*$AD26:$AD33), SUM(G38:G45*$M38:$M45), SUM(X38:X45*$AD38:$AD45),SUM(G50:G56*$M50:$M56), SUM(X50:X56*$AD50:$AD56))} -> 20 | H5: {=SUM(SUM(H14:H21*$M14:$M21),SUM(Y14:Y21*$AD14:$AD21), SUM(H26:H33*$M26:$M33), SUM(Y26:Y33*$AD26:$AD33), SUM(H38:H45*$M38:$M45), SUM(Y38:Y45*$AD38:$AD45),SUM(H50:H56*$M50:$M56), SUM(Y50:Y56*$AD50:$AD56))} -> 16 | I5: {=SUM(SUM(I14:I21*$M14:$M21),SUM(Z14:Z21*$AD14:$AD21), SUM(I26:I33*$M26:$M33), SUM(Z26:Z33*$AD26:$AD33), SUM(I38:I45*$M38:$M45), SUM(Z38:Z45*$AD38:$AD45),SUM(I50:I56*$M50:$M56), SUM(Z50:Z56*$AD50:$AD56))} -> 5 | J5: {=SUM(SUM(J14:J21*$M14:$M21),SUM(AA14:AA21*$AD14:$AD21), SUM(J26:J33*$M26:$M33), SUM(AA26:AA33*$AD26:$AD33), SUM(J38:J45*$M38:$M45), SUM(AA38:AA45*$AD38:$AD45),SUM(J50:J56*$M50:$M56), SUM(AA50:AA56*$AD50:$AD56))} -> 41 | K5: 29 (Min.) | L5: 0.2 | M5: =D5/$D$10 -> 0.20833333
C6: Basic Sciences Requirements | D6: {=SUM(SUM(D14:D21*$N14:$N21),SUM(U14:U21*$AE14:$AE21), SUM(D26:D33*$N26:$N33), SUM(U26:U33*$AE26:$AE33), SUM(D38:D45*$N38:$N45), SUM(U38:U45*$AE38:$AE45),SUM(D50:D56*$N50:$N56), SUM(U50:U56*$AE50:$AE56))} -> 27 | E6: {=SUM(SUM(E14:E21*$N14:$N21),SUM(V14:V21*$AE14:$AE21), SUM(E26:E33*$N26:$N33), SUM(V26:V33*$AE26:$AE33), SUM(E38:E45*$N38:$N45), SUM(V38:V45*$AE38:$AE45),SUM(E50:E56*$N50:$N56), SUM(V50:V56*$AE50:$AE56))} -> 45 | F6: {=SUM(SUM(F14:F21*$N14:$N21),SUM(W14:W21*$AE14:$AE21), SUM(F26:F33*$N26:$N33), SUM(W26:W33*$AE26:$AE33), SUM(F38:F45*$N38:$N45), SUM(W38:W45*$AE38:$AE45),SUM(F50:F56*$N50:$N56), SUM(W50:W56*$AE50:$AE56))} -> 1125 | G6: {=SUM(SUM(G14:G21*$N14:$N21),SUM(X14:X21*$AE14:$AE21), SUM(G26:G33*$N26:$N33), SUM(X26:X33*$AE26:$AE33), SUM(G38:G45*$N38:$N45), SUM(X38:X45*$AE38:$AE45),SUM(G50:G56*$N50:$N56), SUM(X50:X56*$AE50:$AE56))} -> 18 | H6: {=SUM(SUM(H14:H21*$N14:$N21),SUM(Y14:Y21*$AE14:$AE21), SUM(H26:H33*$N26:$N33), SUM(Y26:Y33*$AE26:$AE33), SUM(H38:H45*$N38:$N45), SUM(Y38:Y45*$AE38:$AE45),SUM(H50:H56*$N50:$N56), SUM(Y50:Y56*$AE50:$AE56))} -> 17 | I6: {=SUM(SUM(I14:I21*$N14:$N21),SUM(Z14:Z21*$AE14:$AE21), SUM(I26:I33*$N26:$N33), SUM(Z26:Z33*$AE26:$AE33), SUM(I38:I45*$N38:$N45), SUM(Z38:Z45*$AE38:$AE45),SUM(I50:I56*$N50:$N56), SUM(Z50:Z56*$AE50:$AE56))} -> 2 | J6: {=SUM(SUM(J14:J21*$N14:$N21),SUM(AA14:AA21*$AE14:$AE21), SUM(J26:J33*$N26:$N33), SUM(AA26:AA33*$AE26:$AE33), SUM(J38:J45*$N38:$N45), SUM(AA38:AA45*$AE38:$AE45),SUM(J50:J56*$N50:$N56), SUM(AA50:AA56*$AE50:$AE56))} -> 37 | K6: 24 (Min.) | L6: 0.17 | M6: =D6/$D$10 -> 0.1875
C7: Program Requirements | D7: {=SUM(SUM(D14:D21*$O14:$O21),SUM(U14:U21*$AF14:$AF21), SUM(D26:D33*$O26:$O33), SUM(U26:U33*$AF26:$AF33), SUM(D38:D45*$O38:$O45), SUM(U38:U45*$AF38:$AF45),SUM(D50:D56*$O50:$O56), SUM(U50:U56*$AF50:$AF56))} -> 66 | E7: {=SUM(SUM(E14:E21*$O14:$O21),SUM(V14:V21*$AF14:$AF21), SUM(E26:E33*$O26:$O33), SUM(V26:V33*$AF26:$AF33), SUM(E38:E45*$O38:$O45), SUM(V38:V45*$AF38:$AF45),SUM(E50:E56*$O50:$O56), SUM(V50:V56*$AF50:$AF56))} -> 110 | F7: {=SUM(SUM(F14:F21*$O14:$O21),SUM(W14:W21*$AF14:$AF21), SUM(F26:F33*$O26:$O33), SUM(W26:W33*$AF26:$AF33), SUM(F38:F45*$O38:$O45), SUM(W38:W45*$AF38:$AF45),SUM(F50:F56*$O50:$O56), SUM(W50:W56*$AF50:$AF56))} -> 2750 | G7: {=SUM(SUM(G14:G21*$O14:$O21),SUM(X14:X21*$AF14:$AF21), SUM(G26:G33*$O26:$O33), SUM(X26:X33*$AF26:$AF33), SUM(G38:G45*$O38:$O45), SUM(X38:X45*$AF38:$AF45),SUM(G50:G56*$O50:$O56), SUM(X50:X56*$AF50:$AF56))} -> 40 | H7: {=SUM(SUM(H14:H21*$O14:$O21),SUM(Y14:Y21*$AF14:$AF21), SUM(H26:H33*$O26:$O33), SUM(Y26:Y33*$AF26:$AF33), SUM(H38:H45*$O38:$O45), SUM(Y38:Y45*$AF38:$AF45),SUM(H50:H56*$O50:$O56), SUM(Y50:Y56*$AF50:$AF56))} -> 33 | I7: {=SUM(SUM(I14:I21*$O14:$O21),SUM(Z14:Z21*$AF14:$AF21), SUM(I26:I33*$O26:$O33), SUM(Z26:Z33*$AF26:$AF33), SUM(I38:I45*$O38:$O45), SUM(Z38:Z45*$AF38:$AF45),SUM(I50:I56*$O50:$O56), SUM(Z50:Z56*$AF50:$AF56))} -> 19 | J7: {=SUM(SUM(J14:J21*$O14:$O21),SUM(AA14:AA21*$AF14:$AF21), SUM(J26:J33*$O26:$O33), SUM(AA26:AA33*$AF26:$AF33), SUM(J38:J45*$O38:$O45), SUM(AA38:AA45*$AF38:$AF45),SUM(J50:J56*$O50:$O56), SUM(AA50:AA56*$AF50:$AF56))} -> 92 | K7: 50 (Min.) | L7: 0.35 | M7: =D7/$D$10 -> 0.45833333 | O7: =D4+D5+D7+D8 -> 144 | P7: =E4+E5+E7+E8 -> 240
C8: Major Requirements (Specialization) | D8: {=SUM(SUM(D14:D21*$P14:$P21),SUM(U14:U21*$AG14:$AG21), SUM(D26:D33*$P26:$P33), SUM(U26:U33*$AG26:$AG33), SUM(D38:D45*$P38:$P45), SUM(U38:U45*$AG38:$AG45),SUM(D50:D56*$P50:$P56), SUM(U50:U56*$AG50:$AG56))} -> 36 | E8: {=SUM(SUM(E14:E21*$P14:$P21),SUM(V14:V21*$AG14:$AG21), SUM(E26:E33*$P26:$P33), SUM(V26:V33*$AG26:$AG33), SUM(E38:E45*$P38:$P45), SUM(V38:V45*$AG38:$AG45),SUM(E50:E56*$P50:$P56), SUM(V50:V56*$AG50:$AG56))} -> 60 | F8: {=SUM(SUM(F14:F21*$P14:$P21),SUM(W14:W21*$AG14:$AG21), SUM(F26:F33*$P26:$P33), SUM(W26:W33*$AG26:$AG33), SUM(F38:F45*$P38:$P45), SUM(W38:W45*$AG38:$AG45),SUM(F50:F56*$P50:$P56), SUM(W50:W56*$AG50:$AG56))} -> 1500 | G8: {=SUM(SUM(G14:G21*$P14:$P21),SUM(X14:X21*$AG14:$AG21), SUM(G26:G33*$P26:$P33), SUM(X26:X33*$AG26:$AG33), SUM(G38:G45*$P38:$P45), SUM(X38:X45*$AG38:$AG45),SUM(G50:G56*$P50:$P56), SUM(X50:X56*$AG50:$AG56))} -> 24 | H8: {=SUM(SUM(H14:H21*$P14:$P21),SUM(Y14:Y21*$AG14:$AG21), SUM(H26:H33*$P26:$P33), SUM(Y26:Y33*$AG26:$AG33), SUM(H38:H45*$P38:$P45), SUM(Y38:Y45*$AG38:$AG45),SUM(H50:H56*$P50:$P56), SUM(Y50:Y56*$AG50:$AG56))} -> 19 | I8: {=SUM(SUM(I14:I21*$P14:$P21),SUM(Z14:Z21*$AG14:$AG21), SUM(I26:I33*$P26:$P33), SUM(Z26:Z33*$AG26:$AG33), SUM(I38:I45*$P38:$P45), SUM(Z38:Z45*$AG38:$AG45),SUM(I50:I56*$P50:$P56), SUM(Z50:Z56*$AG50:$AG56))} -> 5 | J8: {=SUM(SUM(J14:J21*$P14:$P21),SUM(AA14:AA21*$AG14:$AG21), SUM(J26:J33*$P26:$P33), SUM(AA26:AA33*$AG26:$AG33), SUM(J38:J45*$P38:$P45), SUM(AA38:AA45*$AG38:$AG45),SUM(J50:J56*$P50:$P56), SUM(AA50:AA56*$AG50:$AG56))} -> 48 | K8: 43 (Max.) | L8: 0.3 | M8: =D8/$D$10 -> 0.25 | O8: =M4+M5+M7+M8 -> 1
C9: Electives | D9: {=SUM(SUM(D14:D21*$Q14:$Q21),SUM(U14:U21*$AH14:$AH21), SUM(D26:D33*$Q26:$Q33), SUM(U26:U33*$AH26:$AH33), SUM(D38:D45*$Q38:$Q45), SUM(U38:U45*$AH38:$AH45),SUM(D50:D56*$Q50:$Q56), SUM(U50:U56*$AH50:$AH56))} -> 24 | E9: {=SUM(SUM(E14:E21*$Q14:$Q21),SUM(V14:V21*$AH14:$AH21), SUM(E26:E33*$Q26:$Q33), SUM(V26:V33*$AH26:$AH33), SUM(E38:E45*$Q38:$Q45), SUM(V38:V45*$AH38:$AH45),SUM(E50:E56*$Q50:$Q56), SUM(V50:V56*$AH50:$AH56))} -> 40 | F9: {=SUM(SUM(F14:F21*$Q14:$Q21),SUM(W14:W21*$AH14:$AH21), SUM(F26:F33*$Q26:$Q33), SUM(W26:W33*$AH26:$AH33), SUM(F38:F45*$Q38:$Q45), SUM(W38:W45*$AH38:$AH45),SUM(F50:F56*$Q50:$Q56), SUM(W50:W56*$AH50:$AH56))} -> 1000 | G9: {=SUM(SUM(G14:G21*$Q14:$Q21),SUM(X14:X21*$AH14:$AH21), SUM(G26:G33*$Q26:$Q33), SUM(X26:X33*$AH26:$AH33), SUM(G38:G45*$Q38:$Q45), SUM(X38:X45*$AH38:$AH45),SUM(G50:G56*$Q50:$Q56), SUM(X50:X56*$AH50:$AH56))} -> 17 | H9: {=SUM(SUM(H14:H21*$Q14:$Q21),SUM(Y14:Y21*$AH14:$AH21), SUM(H26:H33*$Q26:$Q33), SUM(Y26:Y33*$AH26:$AH33), SUM(H38:H45*$Q38:$Q45), SUM(Y38:Y45*$AH38:$AH45),SUM(H50:H56*$Q50:$Q56), SUM(Y50:Y56*$AH50:$AH56))} -> 10 | I9: {=SUM(SUM(I14:I21*$Q14:$Q21),SUM(Z14:Z21*$AH14:$AH21), SUM(I26:I33*$Q26:$Q33), SUM(Z26:Z33*$AH26:$AH33), SUM(I38:I45*$Q38:$Q45), SUM(Z38:Z45*$AH38:$AH45),SUM(I50:I56*$Q50:$Q56), SUM(Z50:Z56*$AH50:$AH56))} -> 4 | J9: {=SUM(SUM(J14:J21*$Q14:$Q21),SUM(AA14:AA21*$AH14:$AH21), SUM(J26:J33*$Q26:$Q33), SUM(AA26:AA33*$AH26:$AH33), SUM(J38:J45*$Q38:$Q45), SUM(AA38:AA45*$AH38:$AH45),SUM(J50:J56*$Q50:$Q56), SUM(AA50:AA56*$AH50:$AH56))} -> 31 | K9: 22 (Min.) | L9: 0.15 | M9: =D9/$D$10 -> 0.16666667
C10: Totals | D10: =D22+U22+D34+U34+D46+U46+D57+U57 -> 144 | E10: =E22+V22+E34+V34+E46+V46+E57+V57 -> 240 | F10: =F22+W22+F34+W34+F46+W46+F57+W57 -> 6000 | G10: =G22+X22+G34+X34+G46+X46+G57+X57 -> 94 | H10: =H22+Y22+H34+Y34+H46+Y46+H57+Y57 -> 70 | I10: =I22+Z22+I34+Z34+I46+Z46+I57+Z57 -> 31 | J10: =J22+AA22+J34+AA34+J46+AA46+J57+AA57 -> 195
A12: Fall Y1 | B12: Code | C12: Course Title | D12: Credits and SWL | G12: Contact Hours | K12: PreReq. | L12: Univ | M12: EAS | N12: Basic Sc. | O12: Prog | P12: Major | Q12: Elec | R12: Spring Y1 | S12: Code | T12: Course Title | U12: Credits and SWL | X12: Contact Hours | AB12: PreReq. | AC12: Univ | AD12: EAS | AE12: Basic Sc. | AF12: Prog | AG12: Major | AH12: Elec
D13: CH | E13: ECTS | F13: SWL | G13: Lec | H13: Tut | I13: Lab | J13: TT | U13: CH | V13: ECTS | W13: SWL | X13: Lec | Y13: Tut | Z13: Lab | AA13: TT
B14: ='List of Courses'!B4 -> EGL111 | C14: ='List of Courses'!C4 -> English I | D14: ='List of Courses'!D4 -> 0 | E14: ='List of Courses'!E4 -> 0 | F14: ='List of Courses'!F4 -> 0 | G14: ='List of Courses'!G4 -> 0 | H14: ='List of Courses'!H4 -> 0 | I14: ='List of Courses'!I4 -> 0 | ... Q14: ='List of Courses'!Q4 -> 0 | S14: ='List of Courses'!B5 -> EGL112 | T14: ='List of Courses'!C5 -> English II | U14: ='List of Courses'!D5 -> 0 | V14: ='List of Courses'!E5 -> 0 | W14: ='List of Courses'!F5 -> 0 | X14: ='List of Courses'!G5 -> 0 | Y14: ='List of Courses'!H5 -> 0 | Z14: ='List of Courses'!I5 -> 0 | ... AH14: ='List of Courses'!Q5 -> 0
B15: ='List of Courses'!B8 -> CSC111 | C15: ='List of Courses'!C8 -> Computer and Information Skills | D15: ='List of Courses'!D8 -> 3 | E15: ='List of Courses'!E8 -> 5 | F15: ='List of Courses'!F8 -> 125 | G15: ='List of Courses'!G8 -> 1 | H15: ='List of Courses'!H8 -> 2 | I15: ='List of Courses'!I8 -> 2 | ... Q15: ='List of Courses'!Q8 -> 0 | S15: ='List of Courses'!B9 -> HUM E1 | T15: ='List of Courses'!C9 -> Humanities and Social Sciences Electives | U15: ='List of Courses'!D9 -> 3 | V15: ='List of Courses'!E9 -> 5 | W15: ='List of Courses'!F9 -> 125 | X15: ='List of Courses'!G9 -> 3 | Y15: ='List of Courses'!H9 -> 0 | Z15: ='List of Courses'!I9 -> 0 | ... AH15: ='List of Courses'!Q9 -> 1
B16: ='List of Courses'!B10 -> MTH111 | C16: ='List of Courses'!C10 -> Analytical Geometry and Calculus I | D16: ='List of Courses'!D10 -> 3 | E16: ='List of Courses'!E10 -> 5 | F16: ='List of Courses'!F10 -> 125 | G16: ='List of Courses'!G10 -> 2 | H16: ='List of Courses'!H10 -> 2 | I16: ='List of Courses'!I10 -> 0 | ... Q16: ='List of Courses'!Q10 -> 0 | S16: ='List of Courses'!B11 -> MTH112 | T16: ='List of Courses'!C11 -> Calculus II | U16: ='List of Courses'!D11 -> 3 | V16: ='List of Courses'!E11 -> 5 | W16: ='List of Courses'!F11 -> 125 | X16: ='List of Courses'!G11 -> 2 | Y16: ='List of Courses'!H11 -> 2 | Z16: ='List of Courses'!I11 -> 0 | ... AH16: ='List of Courses'!Q11 -> 0
B17: ='List of Courses'!B20 -> PHY111 | C17: ='List of Courses'!C20 -> Physics I | D17: ='List of Courses'!D20 -> 3 | E17: ='List of Courses'!E20 -> 5 | F17: ='List of Courses'!F20 -> 125 | G17: ='List of Courses'!G20 -> 2 | H17: ='List of Courses'!H20 -> 2 | I17: ='List of Courses'!I20 -> 1 | ... Q17: ='List of Courses'!Q20 -> 0 | S17: ='List of Courses'!B12 -> MTH113 | T17: ='List of Courses'!C12 -> Probability and Statistics | U17: ='List of Courses'!D12 -> 3 | V17: ='List of Courses'!E12 -> 5 | W17: ='List of Courses'!F12 -> 125 | X17: ='List of Courses'!G12 -> 2 | Y17: ='List of Courses'!H12 -> 2 | Z17: ='List of Courses'!I12 -> 0 | ... AH17: ='List of Courses'!Q12 -> 0
B18: ='List of Courses'!B23 -> MEC111 | C18: ='List of Courses'!C23 -> Engineering Mechanics I - Statics | D18: ='List of Courses'!D23 -> 3 | E18: ='List of Courses'!E23 -> 5 | F18: ='List of Courses'!F23 -> 125 | G18: ='List of Courses'!G23 -> 2 | H18: ='List of Courses'!H23 -> 2 | I18: ='List of Courses'!I23 -> 0 | ... Q18: ='List of Courses'!Q23 -> 0 | S18: ='List of Courses'!B22 -> CHM111 | T18: ='List of Courses'!C22 -> Chemistry Principles | U18: ='List of Courses'!D22 -> 3 | V18: ='List of Courses'!E22 -> 5 | W18: ='List of Courses'!F22 -> 125 | X18: ='List of Courses'!G22 -> 2 | Y18: ='List of Courses'!H22 -> 1 | Z18: ='List of Courses'!I22 -> 1 | ... AH18: ='List of Courses'!Q22 -> 0
B19: ='List of Courses'!B25 -> INT121 | C19: ='List of Courses'!C25 -> Engineering Drawing | D19: ='List of Courses'!D25 -> 3 | E19: ='List of Courses'!E25 -> 5 | F19: ='List of Courses'!F25 -> 125 | G19: ='List of Courses'!G25 -> 2 | H19: ='List of Courses'!H25 -> 0 | I19: ='List of Courses'!I25 -> 2 | ... Q19: ='List of Courses'!Q25 -> 0 | S19: ='List of Courses'!B29 -> ECE151 | T19: ='List of Courses'!C29 -> Introduction to Programming | U19: ='List of Courses'!D29 -> 3 | V19: ='List of Courses'!E29 -> 5 | W19: ='List of Courses'!F29 -> 125 | X19: ='List of Courses'!G29 -> 2 | Y19: ='List of Courses'!H29 -> 0 | Z19: ='List of Courses'!I29 -> 2 | ... AH19: ='List of Courses'!Q29 -> 0
B20: ='List of Courses'!B26 -> INT E1 | C20: ='List of Courses'!C26 -> Engineering History Electives | D20: ='List of Courses'!D26 -> 3 | E20: ='List of Courses'!E26 -> 5 | F20: ='List of Courses'!F26 -> 125 | G20: ='List of Courses'!G26 -> 2 | H20: ='List of Courses'!H26 -> 2 | I20: ='List of Courses'!I26 -> 0 | ... Q20: ='List of Courses'!Q26 -> 1 | S20: ='List of Courses'!B30 -> CVL211 | T20: ='List of Courses'!C30 -> Structural Analysis-1 | U20: ='List of Courses'!D30 -> 3 | V20: ='List of Courses'!E30 -> 5 | W20: ='List of Courses'!F30 -> 125 | X20: ='List of Courses'!G30 -> 2 | Y20: ='List of Courses'!H30 -> 2 | Z20: ='List of Courses'!I30 -> 0 | ... AH20: ='List of Courses'!Q30 -> 0
D22: =SUM(D14:D21) -> 18 | E22: =SUM(E14:E21) -> 30 | F22: =SUM(F14:F21) -> 750 | G22: =SUM(G14:G21) -> 11 | H22: =SUM(H14:H21) -> 10 | I22: =SUM(I14:I21) -> 5 | J22: =SUM(J14:J21) -> 26 | U22: =SUM(U14:U21) -> 18 | V22: =SUM(V14:V21) -> 30 | W22: =SUM(W14:W21) -> 750 | X22: =SUM(X14:X21) -> 13 | Y22: =SUM(Y14:Y21) -> 7 | Z22: =SUM(Z14:Z21) -> 3 | AA22: =SUM(AA14:AA21) -> 23
A24: Fall Y2 | B24: Code | C24: Course Title | D24: Credits and SWL | G24: Contact Hours | K24: PreReq. | L24: Univ | M24: EAS | N24: Basic Sc. | O24: Prog | P24: Major | Q24: Elec | R24: Spring Y2 | S24: Code | T24: Course Title | U24: Credits and SWL | X24: Contact Hours | AB24: PreReq. | AC24: Univ | AD24: EAS | AE24: Basic Sc. | AF24: Prog | AG24: Major | AH24: Elec
D25: CH | E25: ECTS | F25: SWL | G25: Lec | H25: Tut | I25: Lab | J25: TT | U25: CH | V25: ECTS | W25: SWL | X25: Lec | Y25: Tut | Z25: Lab | AA25: TT
B26: ='List of Courses'!B6 -> EGL213 | C26: ='List of Courses'!C6 -> Writing Skills | D26: ='List of Courses'!D6 -> 3 | E26: ='List of Courses'!E6 -> 5 | F26: ='List of Courses'!F6 -> 125 | G26: ='List of Courses'!G6 -> 3 | H26: ='List of Courses'!H6 -> 0 | I26: ='List of Courses'!I6 -> 0 | ... Q26: ='List of Courses'!Q6 -> 0 | S26: ='List of Courses'!B7 -> EGL214 | T26: ='List of Courses'!C7 -> Communication and Presentation Skills | U26: ='List of Courses'!D7 -> 3 | V26: ='List of Courses'!E7 -> 5 | W26: ='List of Courses'!F7 -> 125 | X26: ='List of Courses'!G7 -> 3 | Y26: ='List of Courses'!H7 -> 0 | Z26: ='List of Courses'!I7 -> 0 | ... AH26: ='List of Courses'!Q7 -> 0
B27: ='List of Courses'!B13 -> MTH214 | C27: ='List of Courses'!C13 -> Linear Algebra & Introduction to Machine Learning | D27: ='List of Courses'!D13 -> 3 | E27: ='List of Courses'!E13 -> 5 | F27: ='List of Courses'!F13 -> 125 | G27: ='List of Courses'!G13 -> 2 | H27: ='List of Courses'!H13 -> 2 | I27: ='List of Courses'!I13 -> 0 | ... Q27: ='List of Courses'!Q13 -> 0 | S27: ='List of Courses'!B14 -> MTH215 | T27: ='List of Courses'!C14 -> Differential Equations | U27: ='List of Courses'!D14 -> 3 | V27: ='List of Courses'!E14 -> 5 | W27: ='List of Courses'!F14 -> 125 | X27: ='List of Courses'!G14 -> 2 | Y27: ='List of Courses'!H14 -> 2 | Z27: ='List of Courses'!I14 -> 0 | ... AH27: ='List of Courses'!Q14 -> 0
B28: ='List of Courses'!B34 -> CVL281 | C28: ='List of Courses'!C34 -> Introduction to Surveying | D28: ='List of Courses'!D34 -> 3 | E28: ='List of Courses'!E34 -> 5 | F28: ='List of Courses'!F34 -> 125 | G28: ='List of Courses'!G34 -> 1 | H28: ='List of Courses'!H34 -> 2 | I28: ='List of Courses'!I34 -> 2 | ... Q28: ='List of Courses'!Q34 -> 0 | S28: ='List of Courses'!B33 -> CVL231 | T28: ='List of Courses'!C33 -> Construction Project Management | U28: ='List of Courses'!D33 -> 3 | V28: ='List of Courses'!E33 -> 5 | W28: ='List of Courses'!F33 -> 125 | X28: ='List of Courses'!G33 -> 2 | Y28: ='List of Courses'!H33 -> 2 | Z28: ='List of Courses'!I33 -> 0 | ... AH28: ='List of Courses'!Q33 -> 0
B29: ='List of Courses'!B35 -> CVL282 | C29: ='List of Courses'!C35 -> Civil Engineering Drafting | D29: ='List of Courses'!D35 -> 3 | E29: ='List of Courses'!E35 -> 5 | F29: ='List of Courses'!F35 -> 125 | G29: ='List of Courses'!G35 -> 1 | H29: ='List of Courses'!H35 -> 2 | I29: ='List of Courses'!I35 -> 2 | ... Q29: ='List of Courses'!Q35 -> 0 | S29: ='List of Courses'!B36 -> CVL311 | T29: ='List of Courses'!C36 -> Reinforced Concrete Design-1 | U29: ='List of Courses'!D36 -> 3 | V29: ='List of Courses'!E36 -> 5 | W29: ='List of Courses'!F36 -> 125 | X29: ='List of Courses'!G36 -> 2 | Y29: ='List of Courses'!H36 -> 2 | Z29: ='List of Courses'!I36 -> 0 | ... AH29: ='List of Courses'!Q36 -> 0
B30: ='List of Courses'!B31 -> CVL212 | C30: ='List of Courses'!C31 -> Structural Analysis-2 | D30: ='List of Courses'!D31 -> 3 | E30: ='List of Courses'!E31 -> 5 | F30: ='List of Courses'!F31 -> 125 | G30: ='List of Courses'!G31 -> 2 | H30: ='List of Courses'!H31 -> 2 | I30: ='List of Courses'!I31 -> 0 | ... Q30: ='List of Courses'!Q31 -> 0 | S30: ='List of Courses'!B41 -> CVL321 | T30: ='List of Courses'!C41 -> Engineering Materials-2 | U30: ='List of Courses'!D41 -> 3 | V30: ='List of Courses'!E41 -> 5 | W30: ='List of Courses'!F41 -> 125 | X30: ='List of Courses'!G41 -> 2 | Y30: ='List of Courses'!H41 -> 1 | Z30: ='List of Courses'!I41 -> 1 | ... AH30: ='List of Courses'!Q41 -> 0
B31: ='List of Courses'!B32 -> CVL221 | C31: ='List of Courses'!C32 -> Engineering Materials-1 | D31: ='List of Courses'!D32 -> 3 | E31: ='List of Courses'!E32 -> 5 | F31: ='List of Courses'!F32 -> 125 | G31: ='List of Courses'!G32 -> 2 | H31: ='List of Courses'!H32 -> 1 | I31: ='List of Courses'!I32 -> 1 | ... Q31: ='List of Courses'!Q32 -> 0 | S31: ='List of Courses'!B42 -> CVL331 | T31: ='List of Courses'!C42 -> Construction Engineering & Methods | U31: ='List of Courses'!D42 -> 3 | V31: ='List of Courses'!E42 -> 5 | W31: ='List of Courses'!F42 -> 125 | X31: ='List of Courses'!G42 -> 2 | Y31: ='List of Courses'!H42 -> 2 | Z31: ='List of Courses'!I42 -> 0 | ... AH31: ='List of Courses'!Q42 -> 0
S32: ='List of Courses'!B49 -> CVL391 | T32: ='List of Courses'!C49 -> Practical Training-1 | U32: ='List of Courses'!D49 -> 0 | V32: ='List of Courses'!E49 -> 0 | W32: ='List of Courses'!F49 -> 0 | X32: ='List of Courses'!G49 -> 0 | Y32: ='List of Courses'!H49 -> 0 | Z32: ='List of Courses'!I49 -> 0 | ... AH32: ='List of Courses'!Q49 -> 0
D34: =SUM(D26:D33) -> 18 | E34: =SUM(E26:E33) -> 30 | F34: =SUM(F26:F33) -> 750 | G34: =SUM(G26:G33) -> 11 | H34: =SUM(H26:H33) -> 9 | I34: =SUM(I26:I33) -> 5 | J34: =SUM(J26:J33) -> 25 | U34: =SUM(U26:U33) -> 18 | V34: =SUM(V26:V33) -> 30 | W34: =SUM(W26:W33) -> 750 | X34: =SUM(X26:X33) -> 13 | Y34: =SUM(Y26:Y33) -> 9 | Z34: =SUM(Z26:Z33) -> 1 | AA34: =SUM(AA26:AA33) -> 23
A36: Fall Y3 | B36: Code | C36: Course Title | D36: Credits and SWL | G36: Contact Hours | K36: PreReq. | L36: Univ | M36: EAS | N36: Basic Sc. | O36: Prog | P36: Major | Q36: Elec | R36: Spring Y3 | S36: Code | T36: Course Title | U36: Credits and SWL | X36: Contact Hours | AB36: PreReq. | AC36: Univ | AD36: EAS | AE36: Basic Sc. | AF36: Prog | AG36: Major | AH36: Elec
D37: CH | E37: ECTS | F37: SWL | G37: Lec | H37: Tut | I37: Lab | J37: TT | U37: CH | V37: ECTS | W37: SWL | X37: Lec | Y37: Tut | Z37: Lab | AA37: TT
B38: ='List of Courses'!B37 -> CVL312 | C38: ='List of Courses'!C37 -> Soil Mechanics | D38: ='List of Courses'!D37 -> 3 | E38: ='List of Courses'!E37 -> 5 | F38: ='List of Courses'!F37 -> 125 | G38: ='List of Courses'!G37 -> 2 | H38: ='List of Courses'!H37 -> 1 | I38: ='List of Courses'!I37 -> 1 | ... Q38: ='List of Courses'!Q37 -> 0 | S38: ='List of Courses'!B40 -> CVL315 | T38: ='List of Courses'!C40 -> Structural Steel Design | U38: ='List of Courses'!D40 -> 3 | V38: ='List of Courses'!E40 -> 5 | W38: ='List of Courses'!F40 -> 125 | X38: ='List of Courses'!G40 -> 2 | Y38: ='List of Courses'!H40 -> 2 | Z38: ='List of Courses'!I40 -> 0 | ... AH38: ='List of Courses'!Q40 -> 0
B39: ='List of Courses'!B39 -> CVL314 | C39: ='List of Courses'!C39 -> Reinforced Concrete Design-2 | D39: ='List of Courses'!D39 -> 3 | E39: ='List of Courses'!E39 -> 5 | F39: ='List of Courses'!F39 -> 125 | G39: ='List of Courses'!G39 -> 2 | H39: ='List of Courses'!H39 -> 2 | I39: ='List of Courses'!I39 -> 0 | ... Q39: ='List of Courses'!Q39 -> 0 | S39: ='List of Courses'!B45 -> CVL334 | T39: ='List of Courses'!C45 -> Construction Planning & Scheduling | U39: ='List of Courses'!D45 -> 3 | V39: ='List of Courses'!E45 -> 5 | W39: ='List of Courses'!F45 -> 125 | X39: ='List of Courses'!G45 -> 2 | Y39: ='List of Courses'!H45 -> 1 | Z39: ='List of Courses'!I45 -> 1 | ... AH39: ='List of Courses'!Q45 -> 0
B40: ='List of Courses'!B43 -> CVL332 | C40: ='List of Courses'!C43 -> Quantity Surveying, Estimation and Specifications | D40: ='List of Courses'!D43 -> 3 | E40: ='List of Courses'!E43 -> 5 | F40: ='List of Courses'!F43 -> 125 | G40: ='List of Courses'!G43 -> 2 | H40: ='List of Courses'!H43 -> 2 | I40: ='List of Courses'!I43 -> 0 | ... Q40: ='List of Courses'!Q43 -> 0 | S40: ='List of Courses'!B50 -> CVL392 | T40: ='List of Courses'!C50 -> Practical Training-2 | U40: ='List of Courses'!D50 -> 0 | V40: ='List of Courses'!E50 -> 0 | W40: ='List of Courses'!F50 -> 0 | X40: ='List of Courses'!G50 -> 0 | Y40: ='List of Courses'!H50 -> 0 | Z40: ='List of Courses'!I50 -> 0 | ... AH40: ='List of Courses'!Q50 -> 0
B41: ='List of Courses'!B44 -> CVL333 | C41: ='List of Courses'!C44 -> Civil Engineering Economics | D41: ='List of Courses'!D44 -> 3 | E41: ='List of Courses'!E44 -> 5 | F41: ='List of Courses'!F44 -> 125 | G41: ='List of Courses'!G44 -> 2 | H41: ='List of Courses'!H44 -> 2 | I41: ='List of Courses'!I44 -> 0 | ... Q41: ='List of Courses'!Q44 -> 0 | S41: ='List of Courses'!B51 -> CVL411 | T41: ='List of Courses'!C51 -> Design & Construction of Foundations | U41: ='List of Courses'!D51 -> 3 | V41: ='List of Courses'!E51 -> 5 | W41: ='List of Courses'!F51 -> 125 | X41: ='List of Courses'!G51 -> 2 | Y41: ='List of Courses'!H51 -> 2 | Z41: ='List of Courses'!I51 -> 0 | ... AH41: ='List of Courses'!Q51 -> 0
B42: ='List of Courses'!B46 -> CVL341 | C42: ='List of Courses'!C46 -> Fluid Mechanics | D42: ='List of Courses'!D46 -> 3 | E42: ='List of Courses'!E46 -> 5 | F42: ='List of Courses'!F46 -> 125 | G42: ='List of Courses'!G46 -> 2 | H42: ='List of Courses'!H46 -> 1 | I42: ='List of Courses'!I46 -> 1 | ... Q42: ='List of Courses'!Q46 -> 0 | S42: ='List of Courses'!B57 -> CVL432 | T42: ='List of Courses'!C57 -> Contracts & Commercial Management | U42: ='List of Courses'!D57 -> 3 | V42: ='List of Courses'!E57 -> 5 | W42: ='List of Courses'!F57 -> 125 | X42: ='List of Courses'!G57 -> 2 | Y42: ='List of Courses'!H57 -> 2 | Z42: ='List of Courses'!I57 -> 0 | ... AH42: ='List of Courses'!Q57 -> 0
B43: ='List of Courses'!B56 -> CVL431 | C43: ='List of Courses'!C56 -> Value & Risk Management in Construction | D43: ='List of Courses'!D56 -> 3 | E43: ='List of Courses'!E56 -> 5 | F43: ='List of Courses'!F56 -> 125 | G43: ='List of Courses'!G56 -> 2 | H43: ='List of Courses'!H56 -> 2 | I43: ='List of Courses'!I56 -> 0 | ... Q43: ='List of Courses'!Q56 -> 0 | S43: ='List of Courses'!B63 -> CVL441 | T43: ='List of Courses'!C63 -> Fundamentals of Hydraulic Engineering | U43: ='List of Courses'!D63 -> 3 | V43: ='List of Courses'!E63 -> 5 | W43: ='List of Courses'!F63 -> 125 | X43: ='List of Courses'!G63 -> 2 | Y43: ='List of Courses'!H63 -> 1 | Z43: ='List of Courses'!I63 -> 1 | ... AH43: ='List of Courses'!Q63 -> 0
S44: ='List of Courses'!B64 -> CVL451 | T44: ='List of Courses'!C64 -> Introduction to Transportation & Highway Engineering | U44: ='List of Courses'!D64 -> 3 | V44: ='List of Courses'!E64 -> 5 | W44: ='List of Courses'!F64 -> 125 | X44: ='List of Courses'!G64 -> 2 | Y44: ='List of Courses'!H64 -> 1 | Z44: ='List of Courses'!I64 -> 1 | ... AH44: ='List of Courses'!Q64 -> 0
D46: =SUM(D38:D45) -> 18 | E46: =SUM(E38:E45) -> 30 | F46: =SUM(F38:F45) -> 750 | G46: =SUM(G38:G45) -> 12 | H46: =SUM(H38:H45) -> 10 | I46: =SUM(I38:I45) -> 2 | J46: =SUM(J38:J45) -> 24 | U46: =SUM(U38:U45) -> 18 | V46: =SUM(V38:V45) -> 30 | W46: =SUM(W38:W45) -> 750 | X46: =SUM(X38:X45) -> 12 | Y46: =SUM(Y38:Y45) -> 9 | Z46: =SUM(Z38:Z45) -> 3 | AA46: =SUM(AA38:AA45) -> 24
A48: Fall Y4 | B48: Code | C48: Course Title | D48: Credits and SWL | G48: Contact Hours | K48: PreReq. | L48: Univ | M48: EAS | N48: Basic Sc. | O48: Prog | P48: Major | Q48: Elec | R48: Spring Y4 | S48: Code | T48: Course Title | U48: Credits and SWL | X48: Contact Hours | AB48: PreReq. | AC48: Univ | AD48: EAS | AE48: Basic Sc. | AF48: Prog | AG48: Major | AH48: Elec
...

Sheet CCE Major-1 (7 S)
C2: Requirements | D2: Credits and SWL | G2: Contact Hours | K2: TOR CR | L2: TOR % | M2: Actual % | S2: Program "Civil & Construction Engineering - CCE" Major-1 "Construction Engineering & Management" CEM [7-Semesters Study Plan]
D3: CH | E3: ECTS | F3: SWL | G3: Lec | H3: Tut | I3: Lab | J3: TT
C4: University Requirements | D4: {=SUM(SUM(D14:D21*$L14:$L21),SUM(U14:U21*$AC14:$AC21), SUM(D26:D33*$L26:$L33), SUM(U26:U33*$AC26:$AC33), SUM(D38:D45*$L38:$L45), SUM(U38:U45*$AC38:$AC45),SUM(D50:D56*$L50:$L56), SUM(U50:U56*$AC50:$AC56))} -> 12 | E4: {=SUM(SUM(E14:E21*$L14:$L21),SUM(V14:V21*$AC14:$AC21), SUM(E26:E33*$L26:$L33), SUM(V26:V33*$AC26:$AC33), SUM(E38:E45*$L38:$L45), SUM(V38:V45*$AC38:$AC45),SUM(E50:E56*$L50:$L56), SUM(V50:V56*$AC50:$AC56))} -> 20 | F4: {=SUM(SUM(F14:F21*$L14:$L21),SUM(W14:W21*$AC14:$AC21), SUM(F26:F33*$L26:$L33), SUM(W26:W33*$AC26:$AC33), SUM(F38:F45*$L38:$L45), SUM(W38:W45*$AC38:$AC45),SUM(F50:F56*$L50:$L56), SUM(W50:W56*$AC50:$AC56))} -> 500 | G4: {=SUM(SUM(G14:G21*$L14:$L21),SUM(X14:X21*$AC14:$AC21), SUM(G26:G33*$L26:$L33), SUM(X26:X33*$AC26:$AC33), SUM(G38:G45*$L38:$L45), SUM(X38:X45*$AC38:$AC45),SUM(G50:G56*$L50:$L56), SUM(X50:X56*$AC50:$AC56))} -> 10 | H4: {=SUM(SUM(H14:H21*$L14:$L21),SUM(Y14:Y21*$AC14:$AC21), SUM(H26:H33*$L26:$L33), SUM(Y26:Y33*$AC26:$AC33), SUM(H38:H45*$L38:$L45), SUM(Y38:Y45*$AC38:$AC45),SUM(H50:H56*$L50:$L56), SUM(Y50:Y56*$AC50:$AC56))} -> 2 | I4: {=SUM(SUM(I14:I21*$L14:$L21),SUM(Z14:Z21*$AC14:$AC21), SUM(I26:I33*$L26:$L33), SUM(Z26:Z33*$AC26:$AC33), SUM(I38:I45*$L38:$L45), SUM(Z38:Z45*$AC38:$AC45),SUM(I50:I56*$L50:$L56), SUM(Z50:Z56*$AC50:$AC56))} -> 2 | J4: {=SUM(SUM(J14:J21*$L14:$L21),SUM(AA14:AA21*$AC14:$AC21), SUM(J26:J33*$L26:$L33), SUM(AA26:AA33*$AC26:$AC33), SUM(J38:J45*$L38:$L45), SUM(AA38:AA45*$AC38:$AC45),SUM(J50:J56*$L50:$L56), SUM(AA50:AA56*$AC50:$AC56))} -> 14 | K4: 12 (Min.) | L4: 0.08 | M4: =D4/$D$10 -> 0.083333333
C5: Faculty of Engineering Requirements | D5: {=SUM(SUM(D14:D21*$M14:$M21),SUM(U14:U21*$AD14:$AD21), SUM(D26:D33*$M26:$M33), SUM(U26:U33*$AD26:$AD33), SUM(D38:D45*$M38:$M45), SUM(U38:U45*$AD38:$AD45),SUM(D50:D56*$M50:$M56), SUM(U50:U56*$AD50:$AD56))} -> 30 | E5: {=SUM(SUM(E14:E21*$M14:$M21),SUM(V14:V21*$AD14:$AD21), SUM(E26:E33*$M26:$M33), SUM(V26:V33*$AD26:$AD33), SUM(E38:E45*$M38:$M45), SUM(V38:V45*$AD38:$AD45),SUM(E50:E56*$M50:$M56), SUM(V50:V56*$AD50:$AD56))} -> 50 | F5: {=SUM(SUM(F14:F21*$M14:$M21),SUM(W14:W21*$AD14:$AD21), SUM(F26:F33*$M26:$M33), SUM(W26:W33*$AD26:$AD33), SUM(F38:F45*$M38:$M45), SUM(W38:W45*$AD38:$AD45),SUM(F50:F56*$M50:$M56), SUM(W50:W56*$AD50:$AD56))} -> 1250 | G5: {=SUM(SUM(G14:G21*$M14:$M21),SUM(X14:X21*$AD14:$AD21), SUM(G26:G33*$M26:$M33), SUM(X26:X33*$AD26:$AD33), SUM(G38:G45*$M38:$M45), SUM(X38:X45*$AD38:$AD45),SUM(G50:G56*$M50:$M56), SUM(X50:X56*$AD50:$AD56))} -> 20 | H5: {=SUM(SUM(H14:H21*$M14:$M21),SUM(Y14:Y21*$AD14:$AD21), SUM(H26:H33*$M26:$M33), SUM(Y26:Y33*$AD26:$AD33), SUM(H38:H45*$M38:$M45), SUM(Y38:Y45*$AD38:$AD45),SUM(H50:H56*$M50:$M56), SUM(Y50:Y56*$AD50:$AD56))} -> 16 | I5: {=SUM(SUM(I14:I21*$M14:$M21),SUM(Z14:Z21*$AD14:$AD21), SUM(I26:I33*$M26:$M33), SUM(Z26:Z33*$AD26:$AD33), SUM(I38:I45*$M38:$M45), SUM(Z38:Z45*$AD38:$AD45),SUM(I50:I56*$M50:$M56), SUM(Z50:Z56*$AD50:$AD56))} -> 5 | J5: {=SUM(SUM(J14:J21*$M14:$M21),SUM(AA14:AA21*$AD14:$AD21), SUM(J26:J33*$M26:$M33), SUM(AA26:AA33*$AD26:$AD33), SUM(J38:J45*$M38:$M45), SUM(AA38:AA45*$AD38:$AD45),SUM(J50:J56*$M50:$M56), SUM(AA50:AA56*$AD50:$AD56))} -> 41 | K5: 29 (Min.) | L5: 0.2 | M5: =D5/$D$10 -> 0.20833333
C6: Basic Sciences Requirements | D6: {=SUM(SUM(D14:D21*$N14:$N21),SUM(U14:U21*$AE14:$AE21), SUM(D26:D33*$N26:$N33), SUM(U26:U33*$AE26:$AE33), SUM(D38:D45*$N38:$N45), SUM(U38:U45*$AE38:$AE45),SUM(D50:D56*$N50:$N56), SUM(U50:U56*$AE50:$AE56))} -> 27 | E6: {=SUM(SUM(E14:E21*$N14:$N21),SUM(V14:V21*$AE14:$AE21), SUM(E26:E33*$N26:$N33), SUM(V26:V33*$AE26:$AE33), SUM(E38:E45*$N38:$N45), SUM(V38:V45*$AE38:$AE45),SUM(E50:E56*$N50:$N56), SUM(V50:V56*$AE50:$AE56))} -> 45 | F6: {=SUM(SUM(F14:F21*$N14:$N21),SUM(W14:W21*$AE14:$AE21), SUM(F26:F33*$N26:$N33), SUM(W26:W33*$AE26:$AE33), SUM(F38:F45*$N38:$N45), SUM(W38:W45*$AE38:$AE45),SUM(F50:F56*$N50:$N56), SUM(W50:W56*$AE50:$AE56))} -> 1125 | G6: {=SUM(SUM(G14:G21*$N14:$N21),SUM(X14:X21*$AE14:$AE21), SUM(G26:G33*$N26:$N33), SUM(X26:X33*$AE26:$AE33), SUM(G38:G45*$N38:$N45), SUM(X38:X45*$AE38:$AE45),SUM(G50:G56*$N50:$N56), SUM(X50:X56*$AE50:$AE56))} -> 18 | H6: {=SUM(SUM(H14:H21*$N14:$N21),SUM(Y14:Y21*$AE14:$AE21), SUM(H26:H33*$N26:$N33), SUM(Y26:Y33*$AE26:$AE33), SUM(H38:H45*$N38:$N45), SUM(Y38:Y45*$AE38:$AE45),SUM(H50:H56*$N50:$N56), SUM(Y50:Y56*$AE50:$AE56))} -> 17 | I6: {=SUM(SUM(I14:I21*$N14:$N21),SUM(Z14:Z21*$AE14:$AE21), SUM(I26:I33*$N26:$N33), SUM(Z26:Z33*$AE26:$AE33), SUM(I38:I45*$N38:$N45), SUM(Z38:Z45*$AE38:$AE45),SUM(I50:I56*$N50:$N56), SUM(Z50:Z56*$AE50:$AE56))} -> 2 | J6: {=SUM(SUM(J14:J21*$N14:$N21),SUM(AA14:AA21*$AE14:$AE21), SUM(J26:J33*$N26:$N33), SUM(AA26:AA33*$AE26:$AE33), SUM(J38:J45*$N38:$N45), SUM(AA38:AA45*$AE38:$AE45),SUM(J50:J56*$N50:$N56), SUM(AA50:AA56*$AE50:$AE56))} -> 37 | K6: 24 (Min.) | L6: 0.17 | M6: =D6/$D$10 -> 0.1875
C7: Program Requirements | D7: {=SUM(SUM(D14:D21*$O14:$O21),SUM(U14:U21*$AF14:$AF21), SUM(D26:D33*$O26:$O33), SUM(U26:U33*$AF26:$AF33), SUM(D38:D45*$O38:$O45), SUM(U38:U45*$AF38:$AF45),SUM(D50:D56*$O50:$O56), SUM(U50:U56*$AF50:$AF56))} -> 66 | E7: {=SUM(SUM(E14:E21*$O14:$O21),SUM(V14:V21*$AF14:$AF21), SUM(E26:E33*$O26:$O33), SUM(V26:V33*$AF26:$AF33), SUM(E38:E45*$O38:$O45), SUM(V38:V45*$AF38:$AF45),SUM(E50:E56*$O50:$O56), SUM(V50:V56*$AF50:$AF56))} -> 110 | F7: {=SUM(SUM(F14:F21*$O14:$O21),SUM(W14:W21*$AF14:$AF21), SUM(F26:F33*$O26:$O33), SUM(W26:W33*$AF26:$AF33), SUM(F38:F45*$O38:$O45), SUM(W38:W45*$AF38:$AF45),SUM(F50:F56*$O50:$O56), SUM(W50:W56*$AF50:$AF56))} -> 2750 | G7: {=SUM(SUM(G14:G21*$O14:$O21),SUM(X14:X21*$AF14:$AF21), SUM(G26:G33*$O26:$O33), SUM(X26:X33*$AF26:$AF33), SUM(G38:G45*$O38:$O45), SUM(X38:X45*$AF38:$AF45),SUM(G50:G56*$O50:$O56), SUM(X50:X56*$AF50:$AF56))} -> 40 | H7: {=SUM(SUM(H14:H21*$O14:$O21),SUM(Y14:Y21*$AF14:$AF21), SUM(H26:H33*$O26:$O33), SUM(Y26:Y33*$AF26:$AF33), SUM(H38:H45*$O38:$O45), SUM(Y38:Y45*$AF38:$AF45),SUM(H50:H56*$O50:$O56), SUM(Y50:Y56*$AF50:$AF56))} -> 33 | I7: {=SUM(SUM(I14:I21*$O14:$O21),SUM(Z14:Z21*$AF14:$AF21), SUM(I26:I33*$O26:$O33), SUM(Z26:Z33*$AF26:$AF33), SUM(I38:I45*$O38:$O45), SUM(Z38:Z45*$AF38:$AF45),SUM(I50:I56*$O50:$O56), SUM(Z50:Z56*$AF50:$AF56))} -> 19 | J7: {=SUM(SUM(J14:J21*$O14:$O21),SUM(AA14:AA21*$AF14:$AF21), SUM(J26:J33*$O26:$O33), SUM(AA26:AA33*$AF26:$AF33), SUM(J38:J45*$O38:$O45), SUM(AA38:AA45*$AF38:$AF45),SUM(J50:J56*$O50:$O56), SUM(AA50:AA56*$AF50:$AF56))} -> 92 | K7: 50 (Min.) | L7: 0.35 | M7: =D7/$D$10 -> 0.45833333
C8: Major Requirements (Specialization) | D8: {=SUM(SUM(D14:D21*$P14:$P21),SUM(U14:U21*$AG14:$AG21), SUM(D26:D33*$P26:$P33), SUM(U26:U33*$AG26:$AG33), SUM(D38:D45*$P38:$P45), SUM(U38:U45*$AG38:$AG45),SUM(D50:D56*$P50:$P56), SUM(U50:U56*$AG50:$AG56))} -> 36 | E8: {=SUM(SUM(E14:E21*$P14:$P21),SUM(V14:V21*$AG14:$AG21), SUM(E26:E33*$P26:$P33), SUM(V26:V33*$AG26:$AG33), SUM(E38:E45*$P38:$P45), SUM(V38:V45*$AG38:$AG45),SUM(E50:E56*$P50:$P56), SUM(V50:V56*$AG50:$AG56))} -> 60 | F8: {=SUM(SUM(F14:F21*$P14:$P21),SUM(W14:W21*$AG14:$AG21), SUM(F26:F33*$P26:$P33), SUM(W26:W33*$AG26:$AG33), SUM(F38:F45*$P38:$P45), SUM(W38:W45*$AG38:$AG45),SUM(F50:F56*$P50:$P56), SUM(W50:W56*$AG50:$AG56))} -> 1500 | G8: {=SUM(SUM(G14:G21*$P14:$P21),SUM(X14:X21*$AG14:$AG21), SUM(G26:G33*$P26:$P33), SUM(X26:X33*$AG26:$AG33), SUM(G38:G45*$P38:$P45), SUM(X38:X45*$AG38:$AG45),SUM(G50:G56*$P50:$P56), SUM(X50:X56*$AG50:$AG56))} -> 24 | H8: {=SUM(SUM(H14:H21*$P14:$P21),SUM(Y14:Y21*$AG14:$AG21), SUM(H26:H33*$P26:$P33), SUM(Y26:Y33*$AG26:$AG33), SUM(H38:H45*$P38:$P45), SUM(Y38:Y45*$AG38:$AG45),SUM(H50:H56*$P50:$P56), SUM(Y50:Y56*$AG50:$AG56))} -> 19 | I8: {=SUM(SUM(I14:I21*$P14:$P21),SUM(Z14:Z21*$AG14:$AG21), SUM(I26:I33*$P26:$P33), SUM(Z26:Z33*$AG26:$AG33), SUM(I38:I45*$P38:$P45), SUM(Z38:Z45*$AG38:$AG45),SUM(I50:I56*$P50:$P56), SUM(Z50:Z56*$AG50:$AG56))} -> 5 | J8: {=SUM(SUM(J14:J21*$P14:$P21),SUM(AA14:AA21*$AG14:$AG21), SUM(J26:J33*$P26:$P33), SUM(AA26:AA33*$AG26:$AG33), SUM(J38:J45*$P38:$P45), SUM(AA38:AA45*$AG38:$AG45),SUM(J50:J56*$P50:$P56), SUM(AA50:AA56*$AG50:$AG56))} -> 48 | K8: 43 (Max.) | L8: 0.3 | M8: =D8/$D$10 -> 0.25 | O8: =M4+M5+M7+M8 -> 1
C9: Electives | D9: {=SUM(SUM(D14:D21*$Q14:$Q21),SUM(U14:U21*$AH14:$AH21), SUM(D26:D33*$Q26:$Q33), SUM(U26:U33*$AH26:$AH33), SUM(D38:D45*$Q38:$Q45), SUM(U38:U45*$AH38:$AH45),SUM(D50:D56*$Q50:$Q56), SUM(U50:U56*$AH50:$AH56))} -> 24 | E9: {=SUM(SUM(E14:E21*$Q14:$Q21),SUM(V14:V21*$AH14:$AH21), SUM(E26:E33*$Q26:$Q33), SUM(V26:V33*$AH26:$AH33), SUM(E38:E45*$Q38:$Q45), SUM(V38:V45*$AH38:$AH45),SUM(E50:E56*$Q50:$Q56), SUM(V50:V56*$AH50:$AH56))} -> 40 | F9: {=SUM(SUM(F14:F21*$Q14:$Q21),SUM(W14:W21*$AH14:$AH21), SUM(F26:F33*$Q26:$Q33), SUM(W26:W33*$AH26:$AH33), SUM(F38:F45*$Q38:$Q45), SUM(W38:W45*$AH38:$AH45),SUM(F50:F56*$Q50:$Q56), SUM(W50:W56*$AH50:$AH56))} -> 1000 | G9: {=SUM(SUM(G14:G21*$Q14:$Q21),SUM(X14:X21*$AH14:$AH21), SUM(G26:G33*$Q26:$Q33), SUM(X26:X33*$AH26:$AH33), SUM(G38:G45*$Q38:$Q45), SUM(X38:X45*$AH38:$AH45),SUM(G50:G56*$Q50:$Q56), SUM(X50:X56*$AH50:$AH56))} -> 17 | H9: {=SUM(SUM(H14:H21*$Q14:$Q21),SUM(Y14:Y21*$AH14:$AH21), SUM(H26:H33*$Q26:$Q33), SUM(Y26:Y33*$AH26:$AH33), SUM(H38:H45*$Q38:$Q45), SUM(Y38:Y45*$AH38:$AH45),SUM(H50:H56*$Q50:$Q56), SUM(Y50:Y56*$AH50:$AH56))} -> 10 | I9: {=SUM(SUM(I14:I21*$Q14:$Q21),SUM(Z14:Z21*$AH14:$AH21), SUM(I26:I33*$Q26:$Q33), SUM(Z26:Z33*$AH26:$AH33), SUM(I38:I45*$Q38:$Q45), SUM(Z38:Z45*$AH38:$AH45),SUM(I50:I56*$Q50:$Q56), SUM(Z50:Z56*$AH50:$AH56))} -> 4 | J9: {=SUM(SUM(J14:J21*$Q14:$Q21),SUM(AA14:AA21*$AH14:$AH21), SUM(J26:J33*$Q26:$Q33), SUM(AA26:AA33*$AH26:$AH33), SUM(J38:J45*$Q38:$Q45), SUM(AA38:AA45*$AH38:$AH45),SUM(J50:J56*$Q50:$Q56), SUM(AA50:AA56*$AH50:$AH56))} -> 31 | K9: 22 (Min.) | L9: 0.15 | M9: =D9/$D$10 -> 0.16666667
C10: Totals | D10: =D22+U22+D34+U34+D46+U46+D57+U57 -> 144 | E10: =E22+V22+E34+V34+E46+V46+E57+V57 -> 240 | F10: =F22+W22+F34+W34+F46+W46+F57+W57 -> 6000 | G10: =G22+X22+G34+X34+G46+X46+G57+X57 -> 94 | H10: =H22+Y22+H34+Y34+H46+Y46+H57+Y57 -> 70 | I10: =I22+Z22+I34+Z34+I46+Z46+I57+Z57 -> 31 | J10: =J22+AA22+J34+AA34+J46+AA46+J57+AA57 -> 195
A12: Fall Y1 | B12: Code | C12: Course Title | D12: Credits and SWL | G12: Contact Hours | K12: PreReq. | L12: Univ | M12: EAS | N12: Basic Sc. | O12: Prog | P12: Major | Q12: Elec | R12: Spring Y1 | S12: Code | T12: Course Title | U12: Credits and SWL | X12: Contact Hours | AB12: PreReq. | AC12: Univ | AD12: EAS | AE12: Basic Sc. | AF12: Prog | AG12: Major | AH12: Elec
D13: CH | E13: ECTS | F13: SWL | G13: Lec | H13: Tut | I13: Lab | J13: TT | U13: CH | V13: ECTS | W13: SWL | X13: Lec | Y13: Tut | Z13: Lab | AA13: TT
B14: ='List of Courses'!B4 -> EGL111 | C14: ='List of Courses'!C4 -> English I | D14: ='List of Courses'!D4 -> 0 | E14: ='List of Courses'!E4 -> 0 | F14: ='List of Courses'!F4 -> 0 | G14: ='List of Courses'!G4 -> 0 | H14: ='List of Courses'!H4 -> 0 | I14: ='List of Courses'!I4 -> 0 | ... Q14: ='List of Courses'!Q4 -> 0 | S14: ='List of Courses'!B5 -> EGL112 | T14: ='List of Courses'!C5 -> English II | U14: ='List of Courses'!D5 -> 0 | V14: ='List of Courses'!E5 -> 0 | W14: ='List of Courses'!F5 -> 0 | X14: ='List of Courses'!G5 -> 0 | Y14: ='List of Courses'!H5 -> 0 | Z14: ='List of Courses'!I5 -> 0 | ... AH14: ='List of Courses'!Q5 -> 0
B15: ='List of Courses'!B8 -> CSC111 | C15: ='List of Courses'!C8 -> Computer and Information Skills | D15: ='List of Courses'!D8 -> 3 | E15: ='List of Courses'!E8 -> 5 | F15: ='List of Courses'!F8 -> 125 | G15: ='List of Courses'!G8 -> 1 | H15: ='List of Courses'!H8 -> 2 | I15: ='List of Courses'!I8 -> 2 | ... Q15: ='List of Courses'!Q8 -> 0 | S15: ='List of Courses'!B9 -> HUM E1 | T15: ='List of Courses'!C9 -> Humanities and Social Sciences Electives | U15: ='List of Courses'!D9 -> 3 | V15: ='List of Courses'!E9 -> 5 | W15: ='List of Courses'!F9 -> 125 | X15: ='List of Courses'!G9 -> 3 | Y15: ='List of Courses'!H9 -> 0 | Z15: ='List of Courses'!I9 -> 0 | ... AH15: ='List of Courses'!Q9 -> 1
B16: ='List of Courses'!B10 -> MTH111 | C16: ='List of Courses'!C10 -> Analytical Geometry and Calculus I | D16: ='List of Courses'!D10 -> 3 | E16: ='List of Courses'!E10 -> 5 | F16: ='List of Courses'!F10 -> 125 | G16: ='List of Courses'!G10 -> 2 | H16: ='List of Courses'!H10 -> 2 | I16: ='List of Courses'!I10 -> 0 | ... Q16: ='List of Courses'!Q10 -> 0 | S16: ='List of Courses'!B11 -> MTH112 | T16: ='List of Courses'!C11 -> Calculus II | U16: ='List of Courses'!D11 -> 3 | V16: ='List of Courses'!E11 -> 5 | W16: ='List of Courses'!F11 -> 125 | X16: ='List of Courses'!G11 -> 2 | Y16: ='List of Courses'!H11 -> 2 | Z16: ='List of Courses'!I11 -> 0 | ... AH16: ='List of Courses'!Q11 -> 0
B17: ='List of Courses'!B20 -> PHY111 | C17: ='List of Courses'!C20 -> Physics I | D17: ='List of Courses'!D20 -> 3 | E17: ='List of Courses'!E20 -> 5 | F17: ='List of Courses'!F20 -> 125 | G17: ='List of Courses'!G20 -> 2 | H17: ='List of Courses'!H20 -> 2 | I17: ='List of Courses'!I20 -> 1 | ... Q17: ='List of Courses'!Q20 -> 0 | S17: ='List of Courses'!B12 -> MTH113 | T17: ='List of Courses'!C12 -> Probability and Statistics | U17: ='List of Courses'!D12 -> 3 | V17: ='List of Courses'!E12 -> 5 | W17: ='List of Courses'!F12 -> 125 | X17: ='List of Courses'!G12 -> 2 | Y17: ='List of Courses'!H12 -> 2 | Z17: ='List of Courses'!I12 -> 0 | ... AH17: ='List of Courses'!Q12 -> 0
B18: ='List of Courses'!B23 -> MEC111 | C18: ='List of Courses'!C23 -> Engineering Mechanics I - Statics | D18: ='List of Courses'!D23 -> 3 | E18: ='List of Courses'!E23 -> 5 | F18: ='List of Courses'!F23 -> 125 | G18: ='List of Courses'!G23 -> 2 | H18: ='List of Courses'!H23 -> 2 | I18: ='List of Courses'!I23 -> 0 | ... Q18: ='List of Courses'!Q23 -> 0 | S18: ='List of Courses'!B22 -> CHM111 | T18: ='List of Courses'!C22 -> Chemistry Principles | U18: ='List of Courses'!D22 -> 3 | V18: ='List of Courses'!E22 -> 5 | W18: ='List of Courses'!F22 -> 125 | X18: ='List of Courses'!G22 -> 2 | Y18: ='List of Courses'!H22 -> 1 | Z18: ='List of Courses'!I22 -> 1 | ... AH18: ='List of Courses'!Q22 -> 0
B19: ='List of Courses'!B25 -> INT121 | C19: ='List of Courses'!C25 -> Engineering Drawing | D19: ='List of Courses'!D25 -> 3 | E19: ='List of Courses'!E25 -> 5 | F19: ='List of Courses'!F25 -> 125 | G19: ='List of Courses'!G25 -> 2 | H19: ='List of Courses'!H25 -> 0 | I19: ='List of Courses'!I25 -> 2 | ... Q19: ='List of Courses'!Q25 -> 0 | S19: ='List of Courses'!B29 -> ECE151 | T19: ='List of Courses'!C29 -> Introduction to Programming | U19: ='List of Courses'!D29 -> 3 | V19: ='List of Courses'!E29 -> 5 | W19: ='List of Courses'!F29 -> 125 | X19: ='List of Courses'!G29 -> 2 | Y19: ='List of Courses'!H29 -> 0 | Z19: ='List of Courses'!I29 -> 2 | ... AH19: ='List of Courses'!Q29 -> 0
B20: ='List of Courses'!B26 -> INT E1 | C20: ='List of Courses'!C26 -> Engineering History Electives | D20: ='List of Courses'!D26 -> 3 | E20: ='List of Courses'!E26 -> 5 | F20: ='List of Courses'!F26 -> 125 | G20: ='List of Courses'!G26 -> 2 | H20: ='List of Courses'!H26 -> 2 | I20: ='List of Courses'!I26 -> 0 | ... Q20: ='List of Courses'!Q26 -> 1 | S20: ='List of Courses'!B30 -> CVL211 | T20: ='List of Courses'!C30 -> Structural Analysis-1 | U20: ='List of Courses'!D30 -> 3 | V20: ='List of Courses'!E30 -> 5 | W20: ='List of Courses'!F30 -> 125 | X20: ='List of Courses'!G30 -> 2 | Y20: ='List of Courses'!H30 -> 2 | Z20: ='List of Courses'!I30 -> 0 | ... AH20: ='List of Courses'!Q30 -> 0
S21: ='List of Courses'!B33 -> CVL231 | T21: ='List of Courses'!C33 -> Construction Project Management | U21: ='List of Courses'!D33 -> 3 | V21: ='List of Courses'!E33 -> 5 | W21: ='List of Courses'!F33 -> 125 | X21: ='List of Courses'!G33 -> 2 | Y21: ='List of Courses'!H33 -> 2 | Z21: ='List of Courses'!I33 -> 0 | ... AH21: ='List of Courses'!Q33 -> 0
D22: =SUM(D14:D21) -> 18 | E22: =SUM(E14:E21) -> 30 | F22: =SUM(F14:F21) -> 750 | G22: =SUM(G14:G21) -> 11 | H22: =SUM(H14:H21) -> 10 | I22: =SUM(I14:I21) -> 5 | J22: =SUM(J14:J21) -> 26 | U22: =SUM(U14:U21) -> 21 | V22: =SUM(V14:V21) -> 35 | W22: =SUM(W14:W21) -> 875 | X22: =SUM(X14:X21) -> 15 | Y22: =SUM(Y14:Y21) -> 9 | Z22: =SUM(Z14:Z21) -> 3 | AA22: =SUM(AA14:AA21) -> 27
A24: Fall Y2 | B24: Code | C24: Course Title | D24: Credits and SWL | G24: Contact Hours | K24: PreReq. | L24: Univ | M24: EAS | N24: Basic Sc. | O24: Prog | P24: Major | Q24: Elec | R24: Spring Y2 | S24: Code | T24: Course Title | U24: Credits and SWL | X24: Contact Hours | AB24: PreReq. | AC24: Univ | AD24: EAS | AE24: Basic Sc. | AF24: Prog | AG24: Major | AH24: Elec
D25: CH | E25: ECTS | F25: SWL | G25: Lec | H25: Tut | I25: Lab | J25: TT | U25: CH | V25: ECTS | W25: SWL | X25: Lec | Y25: Tut | Z25: Lab | AA25: TT
B26: ='List of Courses'!B6 -> EGL213 | C26: ='List of Courses'!C6 -> Writing Skills | D26: ='List of Courses'!D6 -> 3 | E26: ='List of Courses'!E6 -> 5 | F26: ='List of Courses'!F6 -> 125 | G26: ='List of Courses'!G6 -> 3 | H26: ='List of Courses'!H6 -> 0 | I26: ='List of Courses'!I6 -> 0 | ... Q26: ='List of Courses'!Q6 -> 0 | S26: ='List of Courses'!B7 -> EGL214 | T26: ='List of Courses'!C7 -> Communication and Presentation Skills | U26: ='List of Courses'!D7 -> 3 | V26: ='List of Courses'!E7 -> 5 | W26: ='List of Courses'!F7 -> 125 | X26: ='List of Courses'!G7 -> 3 | Y26: ='List of Courses'!H7 -> 0 | Z26: ='List of Courses'!I7 -> 0 | ... AH26: ='List of Courses'!Q7 -> 0
B27: ='List of Courses'!B13 -> MTH214 | C27: ='List of Courses'!C13 -> Linear Algebra & Introduction to Machine Learning | D27: ='List of Courses'!D13 -> 3 | E27: ='List of Courses'!E13 -> 5 | F27: ='List of Courses'!F13 -> 125 | G27: ='List of Courses'!G13 -> 2 | H27: ='List of Courses'!H13 -> 2 | I27: ='List of Courses'!I13 -> 0 | ... Q27: ='List of Courses'!Q13 -> 0 | S27: ='List of Courses'!B14 -> MTH215 | T27: ='List of Courses'!C14 -> Differential Equations | U27: ='List of Courses'!D14 -> 3 | V27: ='List of Courses'!E14 -> 5 | W27: ='List of Courses'!F14 -> 125 | X27: ='List of Courses'!G14 -> 2 | Y27: ='List of Courses'!H14 -> 2 | Z27: ='List of Courses'!I14 -> 0 | ... AH27: ='List of Courses'!Q14 -> 0
